Workbook

Sheet Sample
C2: Sample
B4: Overview | F4: INCOME | J4: Left to Spend | N4: Bills & Expenses | Q4: Debt Payments | U4: Savings
B6: Start Date | C6: 45658
B7: End Date | C7: 45688 | F7: =D15 -> 8000 | J7: =D19 -> 814 | N7: =D17 -> 7426 | Q7: =D18 -> 750 | U7: =D16 -> 1010
B8: Currency | C8: $
B9: Start Balance | C9: 2000
B10: spent | C10: =D16+D17+D18 -> 9186 | D10: =D19 -> 814
B11: Cashflow
AD12: debt | AE12: =V49 -> 750
C13: Budget | D13: Actual | AD13: bills | AE13: =J63 -> 2746
B14: Start Balance | C14: =C9 -> 2000 | D14: =C9 -> 2000 | AD14: expenses | AE14: =O63 -> 4680
B15: Income | C15: =C29+C39 -> 7847 | D15: =D29+D39 -> 8000 | I15: =D19 -> 814 | AD15: savings | AE15: =D63 -> 1010
B16: Savings | C16: =C63 -> 810 | D16: =D63 -> 1010
B17: Bills & Expenses | C17: =I63+N63 -> 7557 | D17: =J63+O63 -> 7426
B18: Debt | C18: =U49 -> 760 | D18: =V49 -> 750
B19: Left | C19: =C14+C15-C16-C17-C18 -> 720 | D19: =D14+D15-D17-D18-D16 -> 814
B20: spent | C20: =C19/D19 -> 0.88452088 | D20: =100%-C20 -> 0.11547912
B21: Primary Income | F21: Bills | M21: Expenses | R21: Debt
C23: Estimated | D23: Actual | H23: Due | I23: Budget | J23: Actual | K23: Left | N23: Budget | O23: Actual | P23: Left | T23: Due | U23: Budget | V23: Actual
B24: Paycheck | C24: 3500 | D24: 3500 | F24: TRUE | G24: Netflix | H24: 19 | I24: 16 | J24: 16 | K24: =if(I24="",J24,(if(J24="","",I24-J24))) -> 0 | M24: Transport | N24: 250 | O24: 200 | P24: =if(N24="",O24,(if(O24="","",N24-O24))) -> 50 | R24: FALSE | S24: Credit Card 1 | T24: 6 | U24: 150 | V24: 150
B25: Paycheck 2 | C25: 2500 | D25: 2500 | F25: TRUE | G25: Spotify | H25: 29 | I25: 11 | J25: 11 | K25: =if(I25="",J25,(if(J25="","",I25-J25))) -> 0 | M25: Groceries | N25: 1000 | O25: 850 | P25: =if(N25="",O25,(if(O25="","",N25-O25))) -> 150 | R25: FALSE | S25: Credit Card 2 | T25: 16 | U25: 110 | V25: 100
B26: Bonus | C26: 150 | D26: 200 | F26: TRUE | G26: Rent | H26: 5 | I26: 1800 | J26: 1800 | K26: =if(I26="",J26,(if(J26="","",I26-J26))) -> 0 | M26: Eating Out | N26: 300 | O26: 250 | P26: =if(N26="",O26,(if(O26="","",N26-O26))) -> 50 | R26: FALSE | S26: Student Loan | T26: 9 | U26: 250 | V26: 250
B27: Gifts | C27: 50 | D27: 100 | F27: FALSE | G27: Gas | H27: 7 | I27: 60 | J27: 80 | K27: =if(I27="",J27,(if(J27="","",I27-J27))) -> -20 | M27: Coffee | N27: 45 | O27: 40 | P27: =if(N27="",O27,(if(O27="","",N27-O27))) -> 5 | R27: FALSE | S27: Car Loan | T27: 8 | U27: 250 | V27: 250
B28: Freelancing work | C28: 200 | D28: 150 | F28: FALSE | G28: Electricity | H28: 2 | I28: 160 | J28: 150 | K28: =if(I28="",J28,(if(J28="","",I28-J28))) -> 10 | M28: Fuel | N28: 200 | O28: 180 | P28: =if(N28="",O28,(if(O28="","",N28-O28))) -> 20 | R28: FALSE
B29: Total | C29: =sum(C24:C28) -> 6400 | D29: =sum(D24:D28) -> 6450 | F29: FALSE | G29: Internet | H29: 3 | I29: 75 | J29: 70 | K29: =if(I29="",J29,(if(J29="","",I29-J29))) -> 5 | M29: Health | N29: 250 | O29: 300 | P29: =if(N29="",O29,(if(O29="","",N29-O29))) -> -50 | R29: FALSE
F30: FALSE | G30: Phone | H30: 4 | I30: 90 | J30: 90 | K30: =if(I30="",J30,(if(J30="","",I30-J30))) -> 0 | M30: Beauty | N30: 30 | O30: 50 | P30: =if(N30="",O30,(if(O30="","",N30-O30))) -> -20 | R30: FALSE
B31: Secondary Income | F31: FALSE | G31: Gym | H31: 9 | I31: 40 | J31: 40 | K31: =if(I31="",J31,(if(J31="","",I31-J31))) -> 0 | M31: Clothes | N31: 100 | O31: 150 | P31: =if(N31="",O31,(if(O31="","",N31-O31))) -> -50 | R31: FALSE
F32: FALSE | G32: Prime | H32: 11 | I32: 14 | J32: 14 | K32: =if(I32="",J32,(if(J32="","",I32-J32))) -> 0 | M32: Gifts | N32: 20 | O32: 50 | P32: =if(N32="",O32,(if(O32="","",N32-O32))) -> -30 | R32: FALSE
C33: Estimated | D33: Actual | F33: FALSE | G33: Car | H33: 7 | I33: 450 | J33: 450 | K33: =if(I33="",J33,(if(J33="","",I33-J33))) -> 0 | M33: Entertainment | N33: 200 | O33: 200 | P33: =if(N33="",O33,(if(O33="","",N33-O33))) -> 0 | R33: FALSE
B34: Capital Gains | C34: 50 | D34: 50 | F34: FALSE | G34: Bank Fees | H34: 25 | I34: 26 | J34: 25 | K34: =if(I34="",J34,(if(J34="","",I34-J34))) -> 1 | M34: Mortgage | N34: 2200 | O34: 2200 | P34: =if(N34="",O34,(if(O34="","",N34-O34))) -> 0 | R34: FALSE
B35: Stocks | C35: 25 | D35: 25 | F35: FALSE | K35: =if(I35="",J35,(if(J35="","",I35-J35))) | M35: Car Insurance | N35: 150 | O35: 150 | P35: =if(N35="",O35,(if(O35="","",N35-O35))) -> 0 | R35: FALSE
B36: Rental Income | C36: 1200 | D36: 1200 | F36: FALSE | K36: =if(I36="",J36,(if(J36="","",I36-J36))) | M36: Maintenance | N36: 70 | O36: 60 | P36: =if(N36="",O36,(if(O36="","",N36-O36))) -> 10 | R36: FALSE
B37: Interests | C37: 22 | D37: 25 | F37: FALSE | P37: =if(N37="",O37,(if(O37="","",N37-O37))) | R37: FALSE
B38: Side Hustle | C38: 150 | D38: 250 | F38: FALSE | K38: =if(I38="",J38,(if(J38="","",I38-J38))) | P38: =if(N38="",O38,(if(O38="","",N38-O38))) | R38: FALSE
B39: Total | C39: =SUM(C34:C38) -> 1447 | D39: =sum(D34:D38) -> 1550 | F39: FALSE | K39: =if(I39="",J39,(if(J39="","",I39-J39))) | P39: =if(N39="",O39,(if(O39="","",N39-O39))) | R39: FALSE
F40: FALSE | K40: =if(I40="",J40,(if(J40="","",I40-J40))) | P40: =if(N40="",O40,(if(O40="","",N40-O40))) | R40: FALSE
B41: Saving For | F41: FALSE | K41: =if(I41="",J41,(if(J41="","",I41-J41))) | P41: =if(N41="",O41,(if(O41="","",N41-O41))) | R41: FALSE
F42: FALSE | K42: =if(I42="",J42,(if(J42="","",I42-J42))) | P42: =if(N42="",O42,(if(O42="","",N42-O42))) | R42: FALSE
C43: Budget | D43: Actual | F43: FALSE | K43: =if(I43="",J43,(if(J43="","",I43-J43))) | P43: =if(N43="",O43,(if(O43="","",N43-O43))) | R43: FALSE
B44: Car | C44: 150 | D44: 200 | F44: FALSE | K44: =if(I44="",J44,(if(J44="","",I44-J44))) | P44: =if(N44="",O44,(if(O44="","",N44-O44))) | R44: FALSE
...

Sheet Annual
C2: Annual Summary
B4: Overview | F4: TOTAL INCOME | I4: TOTAL LEFT TO SPEND | M4: TOTAL BILLS & EXPENSES | Q4: TOTAL DEBT PAID | U4: TOTAL SAVED
B6: Start Date | C6: 45658
B7: End Date | C7: 46022 | F7: =January!F7+Feburary!F7+March!F7+April!F7+May!F7+June!F7+July!F7+August!F7+September!F7+October!F7+November!F7+December!F7 -> 0 | I7: =December!J7 -> 0 | M7: =January!N7+Feburary!N7+March!N7+April!N7+May!N7+June!N7+July!N7+August!N7+September!N7+October!N7+November!N7+December!N7 -> 0 | Q7: =January!Q7+Feburary!Q7+March!Q7+April!Q7+May!Q7+June!Q7+July!Q7+August!Q7+September!Q7+October!Q7+November!Q7+December!Q7 -> 0 | U7: =January!U7+Feburary!U7+March!U7+April!U7+May!U7+June!U7+July!U7+August!U7+September!U7+October!U7+November!U7+December!U7 -> 0
B8: Currency | C8: $
B9: Start Balance
B10: spent | C10: =D16+D17+D18 -> 0 | D10: =D19 -> 0
B11: Cashflow
AD12: debt | AE12: =R36 -> 0
C13: Budget | D13: Actual | AD13: bills | AE13: =H36 -> 0
B14: Start Balance | C14: =C9 | D14: =C9 | AD14: expenses | AE14: =M36 -> 0
B15: Income | C15: =C36 -> 0 | D15: =D36 -> 0 | AD15: savings | AE15: =V36 -> 0
B16: Savings | C16: =U36 -> 0 | D16: =V36 -> 0
B17: Bills & Expenses | C17: =G36+M36 -> 0 | D17: =H36+M36 -> 0
B18: Debt | C18: =Q36 -> 0 | D18: =R36 -> 0
B19: Left | C19: =C14+C15-C16-C17-C18 -> 0 | D19: =D14+D15-D17-D18-D16 -> 0
B21: Income | F21: Bills | K21: Expenses | P21: Debt | T21: Savings
B23: Month | C23: Estimated | D23: Actual | F23: Month | G23: Budget | H23: Actual | I23: Difference | K23: Month | L23: Budget | M23: Actual | N23: Difference | P23: Month | Q23: Budget | R23: Actual | T23: Month | U23: Budget | V23: Actual | AC23: Months | AD23: Income | AE23: Expenses
B24: January | C24: =January!C29+January!C39 -> 0 | D24: =January!D29+January!D39 -> 0 | F24: January | G24: =January!I63 -> 0 | H24: =January!J63 -> 0 | I24: =if(G24="",H24,(if(H24="","",G24-H24))) -> 0 | K24: January | L24: =January!N63 -> 0 | M24: =January!O63 -> 0 | N24: =if(L24="",M24,(if(M24="","",L24-M24))) -> 0 | P24: January | Q24: =January!U49 -> 0 | R24: =January!V49 -> 0 | T24: January | U24: =January!C63 -> 0 | V24: =January!D63 -> 0 | AC24: January | AD24: =January!D29+January!D39 -> 0 | AE24: =H24+M24+R24+V24 -> 0
B25: Feburary | C25: =Feburary!C29+Feburary!C39 -> 0 | D25: =Feburary!D29+Feburary!D39 -> 0 | F25: Feburary | G25: =Feburary!I63 -> 0 | H25: =Feburary!J63 -> 0 | I25: =if(G25="",H25,(if(H25="","",G25-H25))) -> 0 | K25: Feburary | L25: =Feburary!N63 -> 0 | M25: =Feburary!O63 -> 0 | N25: =if(L25="",M25,(if(M25="","",L25-M25))) -> 0 | P25: Feburary | Q25: =Feburary!U49 -> 0 | R25: =Feburary!V49 -> 0 | T25: Feburary | U25: =Feburary!C63 -> 0 | V25: =Feburary!D63 -> 0 | AC25: Feburary | AD25: =Feburary!D29+Feburary!D39 -> 0 | AE25: =H25+M25+R25+V25 -> 0
B26: March | C26: =March!C29+March!C39 -> 0 | D26: =March!D29+March!D39 -> 0 | F26: March | G26: =March!I63 -> 0 | H26: =March!J63 -> 0 | I26: =if(G26="",H26,(if(H26="","",G26-H26))) -> 0 | K26: March | L26: =March!N63 -> 0 | M26: =March!O63 -> 0 | N26: =if(L26="",M26,(if(M26="","",L26-M26))) -> 0 | P26: March | Q26: =March!U49 -> 0 | R26: =March!V49 -> 0 | T26: March | U26: =March!C63 -> 0 | V26: =March!D63 -> 0 | AC26: March | AD26: =March!D29+March!D39 -> 0 | AE26: =H26+M26+R26+V26 -> 0
B27: April | C27: =April!C29+April!C39 -> 0 | D27: =April!D29+April!D39 -> 0 | F27: April | G27: =April!I63 -> 0 | H27: =April!J63 -> 0 | I27: =if(G27="",H27,(if(H27="","",G27-H27))) -> 0 | K27: April | L27: =April!N63 -> 0 | M27: =April!O63 -> 0 | N27: =if(L27="",M27,(if(M27="","",L27-M27))) -> 0 | P27: April | Q27: =April!U49 -> 0 | R27: =April!V49 -> 0 | T27: April | U27: =April!C63 -> 0 | V27: =April!D63 -> 0 | AC27: April | AD27: =April!D29+April!D39 -> 0 | AE27: =H27+M27+R27+V27 -> 0
B28: May | C28: =May!C29+May!C39 -> 0 | D28: =May!D29+May!D39 -> 0 | F28: May | G28: =May!I63 -> 0 | H28: =May!J63 -> 0 | I28: =if(G28="",H28,(if(H28="","",G28-H28))) -> 0 | K28: May | L28: =May!N63 -> 0 | M28: =May!O63 -> 0 | N28: =if(L28="",M28,(if(M28="","",L28-M28))) -> 0 | P28: May | Q28: =May!U49 -> 0 | R28: =May!V49 -> 0 | T28: May | U28: =May!C63 -> 0 | V28: =May!D63 -> 0 | AC28: May | AD28: =May!D29+May!D39 -> 0 | AE28: =H28+M28+R28+V28 -> 0
B29: June | C29: =June!C29+June!C39 -> 0 | D29: =June!D29+June!D39 -> 0 | F29: June | G29: =June!I63 -> 0 | H29: =June!J63 -> 0 | I29: =if(G29="",H29,(if(H29="","",G29-H29))) -> 0 | K29: June | L29: =June!N63 -> 0 | M29: =June!O63 -> 0 | N29: =if(L29="",M29,(if(M29="","",L29-M29))) -> 0 | P29: June | Q29: =June!U49 -> 0 | R29: =June!V49 -> 0 | T29: June | U29: =June!C63 -> 0 | V29: =June!D63 -> 0 | AC29: June | AD29: =June!D29+June!D39 -> 0 | AE29: =H29+M29+R29+V29 -> 0
B30: July | C30: =July!C29+July!C39 -> 0 | D30: =July!D29+July!D39 -> 0 | F30: July | G30: =July!I63 -> 0 | H30: =July!J63 -> 0 | I30: =if(G30="",H30,(if(H30="","",G30-H30))) -> 0 | K30: July | L30: =July!N63 -> 0 | M30: =July!O63 -> 0 | N30: =if(L30="",M30,(if(M30="","",L30-M30))) -> 0 | P30: July | Q30: =July!U49 -> 0 | R30: =July!V49 -> 0 | T30: July | U30: =July!C63 -> 0 | V30: =July!D63 -> 0 | AC30: July | AD30: =July!D29+July!D39 -> 0 | AE30: =H30+M30+R30+V30 -> 0
B31: August | C31: =August!C29+August!C39 -> 0 | D31: =August!D29+August!D39 -> 0 | F31: August | G31: =August!I63 -> 0 | H31: =August!J63 -> 0 | I31: =if(G31="",H31,(if(H31="","",G31-H31))) -> 0 | K31: August | L31: =August!N63 -> 0 | M31: =August!O63 -> 0 | N31: =if(L31="",M31,(if(M31="","",L31-M31))) -> 0 | P31: August | Q31: =August!U49 -> 0 | R31: =August!V49 -> 0 | T31: August | U31: =August!C63 -> 0 | V31: =August!D63 -> 0 | AC31: August | AD31: =August!D29+August!D39 -> 0 | AE31: =H31+M31+R31+V31 -> 0
B32: September | C32: =September!C29+September!C39 -> 0 | D32: =September!D29+September!D39 -> 0 | F32: September | G32: =September!I63 -> 0 | H32: =September!J63 -> 0 | I32: =if(G32="",H32,(if(H32="","",G32-H32))) -> 0 | K32: September | L32: =September!N63 -> 0 | M32: =September!O63 -> 0 | N32: =if(L32="",M32,(if(M32="","",L32-M32))) -> 0 | P32: September | Q32: =September!U49 -> 0 | R32: =September!V49 -> 0 | T32: September | U32: =September!C63 -> 0 | V32: =September!D63 -> 0 | AC32: September | AD32: =September!D29+September!D39 -> 0 | AE32: =H32+M32+R32+V32 -> 0
B33: October | C33: =October!C29+October!C39 -> 0 | D33: =October!D29+October!D39 -> 0 | F33: October | G33: =October!I63 -> 0 | H33: =October!J63 -> 0 | I33: =if(G33="",H33,(if(H33="","",G33-H33))) -> 0 | K33: October | L33: =October!N63 -> 0 | M33: =October!O63 -> 0 | N33: =if(L33="",M33,(if(M33="","",L33-M33))) -> 0 | P33: October | Q33: =October!U49 -> 0 | R33: =October!V49 -> 0 | T33: October | U33: =October!C63 -> 0 | V33: =October!D63 -> 0 | AC33: October | AD33: =October!D29+October!D39 -> 0 | AE33: =H33+M33+R33+V33 -> 0
B34: November | C34: =November!C29+November!C39 -> 0 | D34: =November!D29+November!D39 -> 0 | F34: November | G34: =November!I63 -> 0 | H34: =November!J63 -> 0 | I34: =if(G34="",H34,(if(H34="","",G34-H34))) -> 0 | K34: November | L34: =November!N63 -> 0 | M34: =November!O63 -> 0 | N34: =if(L34="",M34,(if(M34="","",L34-M34))) -> 0 | P34: November | Q34: =November!U49 -> 0 | R34: =November!V49 -> 0 | T34: November | U34: =November!C63 -> 0 | V34: =November!D63 -> 0 | AC34: November | AD34: =November!D29+November!D39 -> 0 | AE34: =H34+M34+R34+V34 -> 0
B35: December | C35: =December!C29+December!C39 -> 0 | D35: =December!D29+December!D39 -> 0 | F35: December | G35: =December!I63 -> 0 | H35: =December!J63 -> 0 | I35: =if(G35="",H35,(if(H35="","",G35-H35))) -> 0 | K35: December | L35: =December!N63 -> 0 | M35: =December!O63 -> 0 | N35: =if(L35="",M35,(if(M35="","",L35-M35))) -> 0 | P35: December | Q35: =December!U49 -> 0 | R35: =December!V49 -> 0 | T35: December | U35: =December!C63 -> 0 | V35: =December!D63 -> 0 | AC35: December | AD35: =December!D29+December!D39 -> 0 | AE35: =H35+M35+R35+V35 -> 0
B36: Total | C36: =SUM(C24:C35) -> 0 | D36: =sum(D24:D35) -> 0 | F36: Total | G36: =SUM(G24:G35) -> 0 | H36: =SUM(H24:H35) -> 0 | I36: =sum(I24:I35) -> 0 | K36: Total | L36: =SUM(L24:L35) -> 0 | M36: =SUM(M24:M35) -> 0 | N36: =SUM(N24:N35) -> 0 | P36: Total | Q36: =SUM(Q24:Q35) -> 0 | R36: =SUM(R24:R35) -> 0 | T36: Total | U36: =SUM(U24:U35) -> 0 | V36: =SUM(V24:V35) -> 0
P37: =if(N37="",O37,(if(O37="","",N37-O37)))

Sheet January
C2: January
B4: Overview | F4: INCOME | J4: Left to Spend | N4: Bills & Expenses | Q4: Debt Payments | U4: Savings
B6: Start Date | C6: 45658
B7: End Date | C7: 45688 | F7: =D15 -> 0 | J7: =D19 -> 0 | N7: =D17 -> 0 | Q7: =D18 -> 0 | U7: =D16 -> 0
B8: Currency | C8: $
B9: Start Balance
B10: spent | C10: =D16+D17+D18 -> 0 | D10: =D19 -> 0
B11: Cashflow
AD12: debt | AE12: =V49 -> 0
C13: Budget | D13: Actual | AD13: bills | AE13: =J63 -> 0
B14: Start Balance | C14: =C9 | D14: =C9 | AD14: expenses | AE14: =O63 -> 0
B15: Income | C15: =C29+C39 -> 0 | D15: =D29+D39 -> 0 | I15: =D19 -> 0 | AD15: savings | AE15: =D63 -> 0
B16: Savings | C16: =C63 -> 0 | D16: =D63 -> 0
B17: Bills & Expenses | C17: =I63+N63 -> 0 | D17: =J63+O63 -> 0
B18: Debt | C18: =U49 -> 0 | D18: =V49 -> 0
B19: Left | C19: =C14+C15-C16-C17-C18 -> 0 | D19: =D14+D15-D17-D18-D16 -> 0
B21: Primary Income | F21: Bills | M21: Expenses | R21: Debt
C23: Estimated | D23: Actual | H23: Due | I23: Budget | J23: Actual | K23: Left | N23: Budget | O23: Actual | P23: Left | T23: Due | U23: Budget | V23: Actual
B24: Paycheck | F24: FALSE | K24: =if(I24="",J24,(if(J24="","",I24-J24))) | P24: =if(N24="",O24,(if(O24="","",N24-O24))) | R24: FALSE
B25: Paycheck 2 | F25: FALSE | K25: =if(I25="",J25,(if(J25="","",I25-J25))) | P25: =if(N25="",O25,(if(O25="","",N25-O25))) | R25: FALSE
B26: Bonus | F26: FALSE | K26: =if(I26="",J26,(if(J26="","",I26-J26))) | P26: =if(N26="",O26,(if(O26="","",N26-O26))) | R26: FALSE
B27: Gifts | F27: FALSE | K27: =if(I27="",J27,(if(J27="","",I27-J27))) | P27: =if(N27="",O27,(if(O27="","",N27-O27))) | R27: FALSE
B28: Freelancing work | F28: FALSE | K28: =if(I28="",J28,(if(J28="","",I28-J28))) | P28: =if(N28="",O28,(if(O28="","",N28-O28))) | R28: FALSE
B29: Total | C29: =sum(C24:C28) -> 0 | D29: =sum(D24:D28) -> 0 | F29: FALSE | K29: =if(I29="",J29,(if(J29="","",I29-J29))) | P29: =if(N29="",O29,(if(O29="","",N29-O29))) | R29: FALSE
F30: FALSE | K30: =if(I30="",J30,(if(J30="","",I30-J30))) | P30: =if(N30="",O30,(if(O30="","",N30-O30))) | R30: FALSE
B31: Secondary Income | F31: FALSE | K31: =if(I31="",J31,(if(J31="","",I31-J31))) | P31: =if(N31="",O31,(if(O31="","",N31-O31))) | R31: FALSE
F32: FALSE | K32: =if(I32="",J32,(if(J32="","",I32-J32))) | P32: =if(N32="",O32,(if(O32="","",N32-O32))) | R32: FALSE
C33: Estimated | D33: Actual | F33: FALSE | K33: =if(I33="",J33,(if(J33="","",I33-J33))) | P33: =if(N33="",O33,(if(O33="","",N33-O33))) | R33: FALSE
B34: Capital Gains | F34: FALSE | K34: =if(I34="",J34,(if(J34="","",I34-J34))) | P34: =if(N34="",O34,(if(O34="","",N34-O34))) | R34: FALSE
B35: Stocks | F35: FALSE | K35: =if(I35="",J35,(if(J35="","",I35-J35))) | P35: =if(N35="",O35,(if(O35="","",N35-O35))) | R35: FALSE
B36: Rental Income | F36: FALSE | K36: =if(I36="",J36,(if(J36="","",I36-J36))) | P36: =if(N36="",O36,(if(O36="","",N36-O36))) | R36: FALSE
B37: Interests | F37: FALSE | P37: =if(N37="",O37,(if(O37="","",N37-O37))) | R37: FALSE
B38: Side Hustle | F38: FALSE | K38: =if(I38="",J38,(if(J38="","",I38-J38))) | P38: =if(N38="",O38,(if(O38="","",N38-O38))) | R38: FALSE
B39: Total | C39: =SUM(C34:C38) -> 0 | D39: =sum(D34:D38) -> 0 | F39: FALSE | K39: =if(I39="",J39,(if(J39="","",I39-J39))) | P39: =if(N39="",O39,(if(O39="","",N39-O39))) | R39: FALSE
F40: FALSE | K40: =if(I40="",J40,(if(J40="","",I40-J40))) | P40: =if(N40="",O40,(if(O40="","",N40-O40))) | R40: FALSE
B41: Saving For | F41: FALSE | K41: =if(I41="",J41,(if(J41="","",I41-J41))) | P41: =if(N41="",O41,(if(O41="","",N41-O41))) | R41: FALSE
F42: FALSE | K42: =if(I42="",J42,(if(J42="","",I42-J42))) | P42: =if(N42="",O42,(if(O42="","",N42-O42))) | R42: FALSE
C43: Budget | D43: Actual | F43: FALSE | K43: =if(I43="",J43,(if(J43="","",I43-J43))) | P43: =if(N43="",O43,(if(O43="","",N43-O43))) | R43: FALSE
B44: Car | F44: FALSE | K44: =if(I44="",J44,(if(J44="","",I44-J44))) | P44: =if(N44="",O44,(if(O44="","",N44-O44))) | R44: FALSE
B45: Renovation | F45: FALSE | K45: =if(I45="",J45,(if(J45="","",I45-J45))) | P45: =if(N45="",O45,(if(O45="","",N45-O45))) | R45: FALSE
...

Sheet Feburary
C2: Feburary
B4: Overview | F4: INCOME | J4: Left to Spend | N4: Bills & Expenses | Q4: Debt Payments | U4: Savings
B6: Start Date | C6: 45689
B7: End Date | C7: 45716 | F7: =D15 -> 0 | J7: =D19 -> 0 | N7: =D17 -> 0 | Q7: =D18 -> 0 | U7: =D16 -> 0
B8: Currency | C8: $
B9: Start Balance | C9: =January!J7 -> 0
B10: spent | C10: =D16+D17+D18 -> 0 | D10: =D19 -> 0
B11: Cashflow
AD12: debt | AE12: =V49 -> 0
C13: Budget | D13: Actual | AD13: bills | AE13: =J63 -> 0
B14: Start Balance | C14: =C9 -> 0 | D14: =C9 -> 0 | AD14: expenses | AE14: =O63 -> 0
B15: Income | C15: =C29+C39 -> 0 | D15: =D29+D39 -> 0 | I15: =D19 -> 0 | AD15: savings | AE15: =D63 -> 0
B16: Savings | C16: =C63 -> 0 | D16: =D63 -> 0
B17: Bills & Expenses | C17: =I63+N63 -> 0 | D17: =J63+O63 -> 0
B18: Debt | C18: =U49 -> 0 | D18: =V49 -> 0
B19: Left | C19: =C14+C15-C16-C17-C18 -> 0 | D19: =D14+D15-D17-D18-D16 -> 0
B21: Primary Income | F21: Bills | M21: Expenses | R21: Debt
C23: Estimated | D23: Actual | H23: Due | I23: Budget | J23: Actual | K23: Left | N23: Budget | O23: Actual | P23: Left | T23: Due | U23: Budget | V23: Actual
B24: Paycheck | F24: FALSE | K24: =if(I24="",J24,(if(J24="","",I24-J24))) | P24: =if(N24="",O24,(if(O24="","",N24-O24))) | R24: FALSE
B25: Paycheck 2 | F25: FALSE | K25: =if(I25="",J25,(if(J25="","",I25-J25))) | P25: =if(N25="",O25,(if(O25="","",N25-O25))) | R25: FALSE
B26: Bonus | F26: FALSE | K26: =if(I26="",J26,(if(J26="","",I26-J26))) | P26: =if(N26="",O26,(if(O26="","",N26-O26))) | R26: FALSE
B27: Gifts | F27: FALSE | K27: =if(I27="",J27,(if(J27="","",I27-J27))) | P27: =if(N27="",O27,(if(O27="","",N27-O27))) | R27: FALSE
B28: Freelancing work | F28: FALSE | K28: =if(I28="",J28,(if(J28="","",I28-J28))) | P28: =if(N28="",O28,(if(O28="","",N28-O28))) | R28: FALSE
B29: Total | C29: =sum(C24:C28) -> 0 | D29: =sum(D24:D28) -> 0 | F29: FALSE | K29: =if(I29="",J29,(if(J29="","",I29-J29))) | P29: =if(N29="",O29,(if(O29="","",N29-O29))) | R29: FALSE
F30: FALSE | K30: =if(I30="",J30,(if(J30="","",I30-J30))) | P30: =if(N30="",O30,(if(O30="","",N30-O30))) | R30: FALSE
B31: Secondary Income | F31: FALSE | K31: =if(I31="",J31,(if(J31="","",I31-J31))) | P31: =if(N31="",O31,(if(O31="","",N31-O31))) | R31: FALSE
F32: FALSE | K32: =if(I32="",J32,(if(J32="","",I32-J32))) | P32: =if(N32="",O32,(if(O32="","",N32-O32))) | R32: FALSE
C33: Estimated | D33: Actual | F33: FALSE | K33: =if(I33="",J33,(if(J33="","",I33-J33))) | P33: =if(N33="",O33,(if(O33="","",N33-O33))) | R33: FALSE
B34: Capital Gains | F34: FALSE | K34: =if(I34="",J34,(if(J34="","",I34-J34))) | P34: =if(N34="",O34,(if(O34="","",N34-O34))) | R34: FALSE
B35: Stocks | F35: FALSE | K35: =if(I35="",J35,(if(J35="","",I35-J35))) | P35: =if(N35="",O35,(if(O35="","",N35-O35))) | R35: FALSE
B36: Rental Income | F36: FALSE | K36: =if(I36="",J36,(if(J36="","",I36-J36))) | P36: =if(N36="",O36,(if(O36="","",N36-O36))) | R36: FALSE
B37: Interests | F37: FALSE | P37: =if(N37="",O37,(if(O37="","",N37-O37))) | R37: FALSE
B38: Side Hustle | F38: FALSE | K38: =if(I38="",J38,(if(J38="","",I38-J38))) | P38: =if(N38="",O38,(if(O38="","",N38-O38))) | R38: FALSE
B39: Total | C39: =SUM(C34:C38) -> 0 | D39: =sum(D34:D38) -> 0 | F39: FALSE | K39: =if(I39="",J39,(if(J39="","",I39-J39))) | P39: =if(N39="",O39,(if(O39="","",N39-O39))) | R39: FALSE
F40: FALSE | K40: =if(I40="",J40,(if(J40="","",I40-J40))) | P40: =if(N40="",O40,(if(O40="","",N40-O40))) | R40: FALSE
B41: Saving For | F41: FALSE | K41: =if(I41="",J41,(if(J41="","",I41-J41))) | P41: =if(N41="",O41,(if(O41="","",N41-O41))) | R41: FALSE
F42: FALSE | K42: =if(I42="",J42,(if(J42="","",I42-J42))) | P42: =if(N42="",O42,(if(O42="","",N42-O42))) | R42: FALSE
C43: Budget | D43: Actual | F43: FALSE | K43: =if(I43="",J43,(if(J43="","",I43-J43))) | P43: =if(N43="",O43,(if(O43="","",N43-O43))) | R43: FALSE
B44: Car | F44: FALSE | K44: =if(I44="",J44,(if(J44="","",I44-J44))) | P44: =if(N44="",O44,(if(O44="","",N44-O44))) | R44: FALSE
B45: Renovation | F45: FALSE | K45: =if(I45="",J45,(if(J45="","",I45-J45))) | P45: =if(N45="",O45,(if(O45="","",N45-O45))) | R45: FALSE
...

Sheet March
C2: March
B4: Overview | F4: INCOME | J4: Left to Spend | N4: Bills & Expenses | Q4: Debt Payments | U4: Savings
B6: Start Date | C6: 45717
B7: End Date | C7: 45747 | F7: =D15 -> 0 | J7: =D19 -> 0 | N7: =D17 -> 0 | Q7: =D18 -> 0 | U7: =D16 -> 0
B8: Currency | C8: $
B9: Start Balance | C9: =Feburary!J7 -> 0
B10: spent | C10: =D16+D17+D18 -> 0 | D10: =D19 -> 0
B11: Cashflow
AD12: debt | AE12: =V49 -> 0
C13: Budget | D13: Actual | AD13: bills | AE13: =J63 -> 0
B14: Start Balance | C14: =C9 -> 0 | D14: =C9 -> 0 | AD14: expenses | AE14: =O63 -> 0
B15: Income | C15: =C29+C39 -> 0 | D15: =D29+D39 -> 0 | I15: =D19 -> 0 | AD15: savings | AE15: =D63 -> 0
B16: Savings | C16: =C63 -> 0 | D16: =D63 -> 0
B17: Bills & Expenses | C17: =I63+N63 -> 0 | D17: =J63+O63 -> 0
B18: Debt | C18: =U49 -> 0 | D18: =V49 -> 0
B19: Left | C19: =C14+C15-C16-C17-C18 -> 0 | D19: =D14+D15-D17-D18-D16 -> 0
B21: Primary Income | F21: Bills | M21: Expenses | R21: Debt
C23: Estimated | D23: Actual | H23: Due | I23: Budget | J23: Actual | K23: Left | N23: Budget | O23: Actual | P23: Left | T23: Due | U23: Budget | V23: Actual
B24: Paycheck | F24: FALSE | K24: =if(I24="",J24,(if(J24="","",I24-J24))) | P24: =if(N24="",O24,(if(O24="","",N24-O24))) | R24: FALSE
B25: Paycheck 2 | F25: FALSE | K25: =if(I25="",J25,(if(J25="","",I25-J25))) | P25: =if(N25="",O25,(if(O25="","",N25-O25))) | R25: FALSE
B26: Bonus | F26: FALSE | K26: =if(I26="",J26,(if(J26="","",I26-J26))) | P26: =if(N26="",O26,(if(O26="","",N26-O26))) | R26: FALSE
B27: Gifts | F27: FALSE | K27: =if(I27="",J27,(if(J27="","",I27-J27))) | P27: =if(N27="",O27,(if(O27="","",N27-O27))) | R27: FALSE
B28: Freelancing work | F28: FALSE | K28: =if(I28="",J28,(if(J28="","",I28-J28))) | P28: =if(N28="",O28,(if(O28="","",N28-O28))) | R28: FALSE
B29: Total | C29: =sum(C24:C28) -> 0 | D29: =sum(D24:D28) -> 0 | F29: FALSE | K29: =if(I29="",J29,(if(J29="","",I29-J29))) | P29: =if(N29="",O29,(if(O29="","",N29-O29))) | R29: FALSE
F30: FALSE | K30: =if(I30="",J30,(if(J30="","",I30-J30))) | P30: =if(N30="",O30,(if(O30="","",N30-O30))) | R30: FALSE
B31: Secondary Income | F31: FALSE | K31: =if(I31="",J31,(if(J31="","",I31-J31))) | P31: =if(N31="",O31,(if(O31="","",N31-O31))) | R31: FALSE
F32: FALSE | K32: =if(I32="",J32,(if(J32="","",I32-J32))) | P32: =if(N32="",O32,(if(O32="","",N32-O32))) | R32: FALSE
C33: Estimated | D33: Actual | F33: FALSE | K33: =if(I33="",J33,(if(J33="","",I33-J33))) | P33: =if(N33="",O33,(if(O33="","",N33-O33))) | R33: FALSE
B34: Capital Gains | F34: FALSE | K34: =if(I34="",J34,(if(J34="","",I34-J34))) | P34: =if(N34="",O34,(if(O34="","",N34-O34))) | R34: FALSE
B35: Stocks | F35: FALSE | K35: =if(I35="",J35,(if(J35="","",I35-J35))) | P35: =if(N35="",O35,(if(O35="","",N35-O35))) | R35: FALSE
B36: Rental Income | F36: FALSE | K36: =if(I36="",J36,(if(J36="","",I36-J36))) | P36: =if(N36="",O36,(if(O36="","",N36-O36))) | R36: FALSE
B37: Interests | F37: FALSE | P37: =if(N37="",O37,(if(O37="","",N37-O37))) | R37: FALSE
B38: Side Hustle | F38: FALSE | K38: =if(I38="",J38,(if(J38="","",I38-J38))) | P38: =if(N38="",O38,(if(O38="","",N38-O38))) | R38: FALSE
B39: Total | C39: =SUM(C34:C38) -> 0 | D39: =sum(D34:D38) -> 0 | F39: FALSE | K39: =if(I39="",J39,(if(J39="","",I39-J39))) | P39: =if(N39="",O39,(if(O39="","",N39-O39))) | R39: FALSE
F40: FALSE | K40: =if(I40="",J40,(if(J40="","",I40-J40))) | P40: =if(N40="",O40,(if(O40="","",N40-O40))) | R40: FALSE
B41: Saving For | F41: FALSE | K41: =if(I41="",J41,(if(J41="","",I41-J41))) | P41: =if(N41="",O41,(if(O41="","",N41-O41))) | R41: FALSE
F42: FALSE | K42: =if(I42="",J42,(if(J42="","",I42-J42))) | P42: =if(N42="",O42,(if(O42="","",N42-O42))) | R42: FALSE
C43: Budget | D43: Actual | F43: FALSE | K43: =if(I43="",J43,(if(J43="","",I43-J43))) | P43: =if(N43="",O43,(if(O43="","",N43-O43))) | R43: FALSE
B44: Car | F44: FALSE | K44: =if(I44="",J44,(if(J44="","",I44-J44))) | P44: =if(N44="",O44,(if(O44="","",N44-O44))) | R44: FALSE
B45: Renovation | F45: FALSE | K45: =if(I45="",J45,(if(J45="","",I45-J45))) | P45: =if(N45="",O45,(if(O45="","",N45-O45))) | R45: FALSE
...

Sheet April
C2: April
B4: Overview | F4: INCOME | J4: Left to Spend | N4: Bills & Expenses | Q4: Debt Payments | U4: Savings
B6: Start Date | C6: 45748
B7: End Date | C7: 45777 | F7: =D15 -> 0 | J7: =D19 -> 0 | N7: =D17 -> 0 | Q7: =D18 -> 0 | U7: =D16 -> 0
B8: Currency | C8: $
B9: Start Balance | C9: =March!J7 -> 0
B10: spent | C10: =D16+D17+D18 -> 0 | D10: =D19 -> 0
B11: Cashflow
AD12: debt | AE12: =V49 -> 0
C13: Budget | D13: Actual | AD13: bills | AE13: =J63 -> 0
B14: Start Balance | C14: =C9 -> 0 | D14: =C9 -> 0 | AD14: expenses | AE14: =O63 -> 0
B15: Income | C15: =C29+C39 -> 0 | D15: =D29+D39 -> 0 | I15: =D19 -> 0 | AD15: savings | AE15: =D63 -> 0
B16: Savings | C16: =C63 -> 0 | D16: =D63 -> 0
B17: Bills & Expenses | C17: =I63+N63 -> 0 | D17: =J63+O63 -> 0
B18: Debt | C18: =U49 -> 0 | D18: =V49 -> 0
B19: Left | C19: =C14+C15-C16-C17-C18 -> 0 | D19: =D14+D15-D17-D18-D16 -> 0
B21: Primary Income | F21: Bills | M21: Expenses | R21: Debt
C23: Estimated | D23: Actual | H23: Due | I23: Budget | J23: Actual | K23: Left | N23: Budget | O23: Actual | P23: Left | T23: Due | U23: Budget | V23: Actual
B24: Paycheck | F24: FALSE | K24: =if(I24="",J24,(if(J24="","",I24-J24))) | P24: =if(N24="",O24,(if(O24="","",N24-O24))) | R24: FALSE
B25: Paycheck 2 | F25: FALSE | K25: =if(I25="",J25,(if(J25="","",I25-J25))) | P25: =if(N25="",O25,(if(O25="","",N25-O25))) | R25: FALSE
B26: Bonus | F26: FALSE | K26: =if(I26="",J26,(if(J26="","",I26-J26))) | P26: =if(N26="",O26,(if(O26="","",N26-O26))) | R26: FALSE
B27: Gifts | F27: FALSE | K27: =if(I27="",J27,(if(J27="","",I27-J27))) | P27: =if(N27="",O27,(if(O27="","",N27-O27))) | R27: FALSE
B28: Freelancing work | F28: FALSE | K28: =if(I28="",J28,(if(J28="","",I28-J28))) | P28: =if(N28="",O28,(if(O28="","",N28-O28))) | R28: FALSE
B29: Total | C29: =sum(C24:C28) -> 0 | D29: =sum(D24:D28) -> 0 | F29: FALSE | K29: =if(I29="",J29,(if(J29="","",I29-J29))) | P29: =if(N29="",O29,(if(O29="","",N29-O29))) | R29: FALSE
F30: FALSE | K30: =if(I30="",J30,(if(J30="","",I30-J30))) | P30: =if(N30="",O30,(if(O30="","",N30-O30))) | R30: FALSE
B31: Secondary Income | F31: FALSE | K31: =if(I31="",J31,(if(J31="","",I31-J31))) | P31: =if(N31="",O31,(if(O31="","",N31-O31))) | R31: FALSE
F32: FALSE | K32: =if(I32="",J32,(if(J32="","",I32-J32))) | P32: =if(N32="",O32,(if(O32="","",N32-O32))) | R32: FALSE
C33: Estimated | D33: Actual | F33: FALSE | K33: =if(I33="",J33,(if(J33="","",I33-J33))) | P33: =if(N33="",O33,(if(O33="","",N33-O33))) | R33: FALSE
B34: Capital Gains | F34: FALSE | K34: =if(I34="",J34,(if(J34="","",I34-J34))) | P34: =if(N34="",O34,(if(O34="","",N34-O34))) | R34: FALSE
B35: Stocks | F35: FALSE | K35: =if(I35="",J35,(if(J35="","",I35-J35))) | P35: =if(N35="",O35,(if(O35="","",N35-O35))) | R35: FALSE
B36: Rental Income | F36: FALSE | K36: =if(I36="",J36,(if(J36="","",I36-J36))) | P36: =if(N36="",O36,(if(O36="","",N36-O36))) | R36: FALSE
B37: Interests | F37: FALSE | P37: =if(N37="",O37,(if(O37="","",N37-O37))) | R37: FALSE
B38: Side Hustle | F38: FALSE | K38: =if(I38="",J38,(if(J38="","",I38-J38))) | P38: =if(N38="",O38,(if(O38="","",N38-O38))) | R38: FALSE
B39: Total | C39: =SUM(C34:C38) -> 0 | D39: =sum(D34:D38) -> 0 | F39: FALSE | K39: =if(I39="",J39,(if(J39="","",I39-J39))) | P39: =if(N39="",O39,(if(O39="","",N39-O39))) | R39: FALSE
F40: FALSE | K40: =if(I40="",J40,(if(J40="","",I40-J40))) | P40: =if(N40="",O40,(if(O40="","",N40-O40))) | R40: FALSE
B41: Saving For | F41: FALSE | K41: =if(I41="",J41,(if(J41="","",I41-J41))) | P41: =if(N41="",O41,(if(O41="","",N41-O41))) | R41: FALSE
F42: FALSE | K42: =if(I42="",J42,(if(J42="","",I42-J42))) | P42: =if(N42="",O42,(if(O42="","",N42-O42))) | R42: FALSE
C43: Budget | D43: Actual | F43: FALSE | K43: =if(I43="",J43,(if(J43="","",I43-J43))) | P43: =if(N43="",O43,(if(O43="","",N43-O43))) | R43: FALSE
B44: Car | F44: FALSE | K44: =if(I44="",J44,(if(J44="","",I44-J44))) | P44: =if(N44="",O44,(if(O44="","",N44-O44))) | R44: FALSE
B45: Renovation | F45: FALSE | K45: =if(I45="",J45,(if(J45="","",I45-J45))) | P45: =if(N45="",O45,(if(O45="","",N45-O45))) | R45: FALSE
...

Sheet May
C2: May
B4: Overview | F4: INCOME | J4: Left to Spend | N4: Bills & Expenses | Q4: Debt Payments | U4: Savings
B6: Start Date | C6: 45778
B7: End Date | C7: 45808 | F7: =D15 -> 0 | J7: =D19 -> 0 | N7: =D17 -> 0 | Q7: =D18 -> 0 | U7: =D16 -> 0
B8: Currency | C8: $
B9: Start Balance | C9: =April!J7 -> 0
B10: spent | C10: =D16+D17+D18 -> 0 | D10: =D19 -> 0
B11: Cashflow
AD12: debt | AE12: =V49 -> 0
C13: Budget | D13: Actual | AD13: bills | AE13: =J63 -> 0
B14: Start Balance | C14: =C9 -> 0 | D14: =C9 -> 0 | AD14: expenses | AE14: =O63 -> 0
B15: Income | C15: =C29+C39 -> 0 | D15: =D29+D39 -> 0 | I15: =D19 -> 0 | AD15: savings | AE15: =D63 -> 0
B16: Savings | C16: =C63 -> 0 | D16: =D63 -> 0
B17: Bills & Expenses | C17: =I63+N63 -> 0 | D17: =J63+O63 -> 0
B18: Debt | C18: =U49 -> 0 | D18: =V49 -> 0
B19: Left | C19: =C14+C15-C16-C17-C18 -> 0 | D19: =D14+D15-D17-D18-D16 -> 0
B21: Primary Income | F21: Bills | M21: Expenses | R21: Debt
C23: Estimated | D23: Actual | H23: Due | I23: Budget | J23: Actual | K23: Left | N23: Budget | O23: Actual | P23: Left | T23: Due | U23: Budget | V23: Actual
B24: Paycheck | F24: FALSE | K24: =if(I24="",J24,(if(J24="","",I24-J24))) | P24: =if(N24="",O24,(if(O24="","",N24-O24))) | R24: FALSE
B25: Paycheck 2 | F25: FALSE | K25: =if(I25="",J25,(if(J25="","",I25-J25))) | P25: =if(N25="",O25,(if(O25="","",N25-O25))) | R25: FALSE
B26: Bonus | F26: FALSE | K26: =if(I26="",J26,(if(J26="","",I26-J26))) | P26: =if(N26="",O26,(if(O26="","",N26-O26))) | R26: FALSE
B27: Gifts | F27: FALSE | K27: =if(I27="",J27,(if(J27="","",I27-J27))) | P27: =if(N27="",O27,(if(O27="","",N27-O27))) | R27: FALSE
B28: Freelancing work | F28: FALSE | K28: =if(I28="",J28,(if(J28="","",I28-J28))) | P28: =if(N28="",O28,(if(O28="","",N28-O28))) | R28: FALSE
B29: Total | C29: =sum(C24:C28) -> 0 | D29: =sum(D24:D28) -> 0 | F29: FALSE | K29: =if(I29="",J29,(if(J29="","",I29-J29))) | P29: =if(N29="",O29,(if(O29="","",N29-O29))) | R29: FALSE
F30: FALSE | K30: =if(I30="",J30,(if(J30="","",I30-J30))) | P30: =if(N30="",O30,(if(O30="","",N30-O30))) | R30: FALSE
B31: Secondary Income | F31: FALSE | K31: =if(I31="",J31,(if(J31="","",I31-J31))) | P31: =if(N31="",O31,(if(O31="","",N31-O31))) | R31: FALSE
F32: FALSE | K32: =if(I32="",J32,(if(J32="","",I32-J32))) | P32: =if(N32="",O32,(if(O32="","",N32-O32))) | R32: FALSE
C33: Estimated | D33: Actual | F33: FALSE | K33: =if(I33="",J33,(if(J33="","",I33-J33))) | P33: =if(N33="",O33,(if(O33="","",N33-O33))) | R33: FALSE
B34: Capital Gains | F34: FALSE | K34: =if(I34="",J34,(if(J34="","",I34-J34))) | P34: =if(N34="",O34,(if(O34="","",N34-O34))) | R34: FALSE
B35: Stocks | F35: FALSE | K35: =if(I35="",J35,(if(J35="","",I35-J35))) | P35: =if(N35="",O35,(if(O35="","",N35-O35))) | R35: FALSE
B36: Rental Income | F36: FALSE | K36: =if(I36="",J36,(if(J36="","",I36-J36))) | P36: =if(N36="",O36,(if(O36="","",N36-O36))) | R36: FALSE
B37: Interests | F37: FALSE | P37: =if(N37="",O37,(if(O37="","",N37-O37))) | R37: FALSE
B38: Side Hustle | F38: FALSE | K38: =if(I38="",J38,(if(J38="","",I38-J38))) | P38: =if(N38="",O38,(if(O38="","",N38-O38))) | R38: FALSE
B39: Total | C39: =SUM(C34:C38) -> 0 | D39: =sum(D34:D38) -> 0 | F39: FALSE | K39: =if(I39="",J39,(if(J39="","",I39-J39))) | P39: =if(N39="",O39,(if(O39="","",N39-O39))) | R39: FALSE
F40: FALSE | K40: =if(I40="",J40,(if(J40="","",I40-J40))) | P40: =if(N40="",O40,(if(O40="","",N40-O40))) | R40: FALSE
B41: Saving For | F41: FALSE | K41: =if(I41="",J41,(if(J41="","",I41-J41))) | P41: =if(N41="",O41,(if(O41="","",N41-O41))) | R41: FALSE
F42: FALSE | K42: =if(I42="",J42,(if(J42="","",I42-J42))) | P42: =if(N42="",O42,(if(O42="","",N42-O42))) | R42: FALSE
C43: Budget | D43: Actual | F43: FALSE | K43: =if(I43="",J43,(if(J43="","",I43-J43))) | P43: =if(N43="",O43,(if(O43="","",N43-O43))) | R43: FALSE
B44: Car | F44: FALSE | K44: =if(I44="",J44,(if(J44="","",I44-J44))) | P44: =if(N44="",O44,(if(O44="","",N44-O44))) | R44: FALSE
B45: Renovation | F45: FALSE | K45: =if(I45="",J45,(if(J45="","",I45-J45))) | P45: =if(N45="",O45,(if(O45="","",N45-O45))) | R45: FALSE
...

Sheet June
C2: June
B4: Overview | F4: INCOME | J4: Left to Spend | N4: Bills & Expenses | Q4: Debt Payments | U4: Savings
B6: Start Date | C6: 45809
B7: End Date | C7: 45838 | F7: =D15 -> 0 | J7: =D19 -> 0 | N7: =D17 -> 0 | Q7: =D18 -> 0 | U7: =D16 -> 0
B8: Currency | C8: $
B9: Start Balance | C9: =May!J7 -> 0
B10: spent | C10: =D16+D17+D18 -> 0 | D10: =D19 -> 0
B11: Cashflow
AD12: debt | AE12: =V49 -> 0
C13: Budget | D13: Actual | AD13: bills | AE13: =J63 -> 0
B14: Start Balance | C14: =C9 -> 0 | D14: =C9 -> 0 | AD14: expenses | AE14: =O63 -> 0
B15: Income | C15: =C29+C39 -> 0 | D15: =D29+D39 -> 0 | I15: =D19 -> 0 | AD15: savings | AE15: =D63 -> 0
B16: Savings | C16: =C63 -> 0 | D16: =D63 -> 0
B17: Bills & Expenses | C17: =I63+N63 -> 0 | D17: =J63+O63 -> 0
B18: Debt | C18: =U49 -> 0 | D18: =V49 -> 0
B19: Left | C19: =C14+C15-C16-C17-C18 -> 0 | D19: =D14+D15-D17-D18-D16 -> 0
B21: Primary Income | F21: Bills | M21: Expenses | R21: Debt
C23: Estimated | D23: Actual | H23: Due | I23: Budget | J23: Actual | K23: Left | N23: Budget | O23: Actual | P23: Left | T23: Due | U23: Budget | V23: Actual
B24: Paycheck | F24: FALSE | K24: =if(I24="",J24,(if(J24="","",I24-J24))) | P24: =if(N24="",O24,(if(O24="","",N24-O24))) | R24: FALSE
B25: Paycheck 2 | F25: FALSE | K25: =if(I25="",J25,(if(J25="","",I25-J25))) | P25: =if(N25="",O25,(if(O25="","",N25-O25))) | R25: FALSE
B26: Bonus | F26: FALSE | K26: =if(I26="",J26,(if(J26="","",I26-J26))) | P26: =if(N26="",O26,(if(O26="","",N26-O26))) | R26: FALSE
B27: Gifts | F27: FALSE | K27: =if(I27="",J27,(if(J27="","",I27-J27))) | P27: =if(N27="",O27,(if(O27="","",N27-O27))) | R27: FALSE
B28: Freelancing work | F28: FALSE | K28: =if(I28="",J28,(if(J28="","",I28-J28))) | P28: =if(N28="",O28,(if(O28="","",N28-O28))) | R28: FALSE
B29: Total | C29: =sum(C24:C28) -> 0 | D29: =sum(D24:D28) -> 0 | F29: FALSE | K29: =if(I29="",J29,(if(J29="","",I29-J29))) | P29: =if(N29="",O29,(if(O29="","",N29-O29))) | R29: FALSE
F30: FALSE | K30: =if(I30="",J30,(if(J30="","",I30-J30))) | P30: =if(N30="",O30,(if(O30="","",N30-O30))) | R30: FALSE
B31: Secondary Income | F31: FALSE | K31: =if(I31="",J31,(if(J31="","",I31-J31))) | P31: =if(N31="",O31,(if(O31="","",N31-O31))) | R31: FALSE
F32: FALSE | K32: =if(I32="",J32,(if(J32="","",I32-J32))) | P32: =if(N32="",O32,(if(O32="","",N32-O32))) | R32: FALSE
C33: Estimated | D33: Actual | F33: FALSE | K33: =if(I33="",J33,(if(J33="","",I33-J33))) | P33: =if(N33="",O33,(if(O33="","",N33-O33))) | R33: FALSE
B34: Capital Gains | F34: FALSE | K34: =if(I34="",J34,(if(J34="","",I34-J34))) | P34: =if(N34="",O34,(if(O34="","",N34-O34))) | R34: FALSE
B35: Stocks | F35: FALSE | K35: =if(I35="",J35,(if(J35="","",I35-J35))) | P35: =if(N35="",O35,(if(O35="","",N35-O35))) | R35: FALSE
B36: Rental Income | F36: FALSE | K36: =if(I36="",J36,(if(J36="","",I36-J36))) | P36: =if(N36="",O36,(if(O36="","",N36-O36))) | R36: FALSE
B37: Interests | F37: FALSE | P37: =if(N37="",O37,(if(O37="","",N37-O37))) | R37: FALSE
B38: Side Hustle | F38: FALSE | K38: =if(I38="",J38,(if(J38="","",I38-J38))) | P38: =if(N38="",O38,(if(O38="","",N38-O38))) | R38: FALSE
B39: Total | C39: =SUM(C34:C38) -> 0 | D39: =sum(D34:D38) -> 0 | F39: FALSE | K39: =if(I39="",J39,(if(J39="","",I39-J39))) | P39: =if(N39="",O39,(if(O39="","",N39-O39))) | R39: FALSE
F40: FALSE | K40: =if(I40="",J40,(if(J40="","",I40-J40))) | P40: =if(N40="",O40,(if(O40="","",N40-O40))) | R40: FALSE
B41: Saving For | F41: FALSE | K41: =if(I41="",J41,(if(J41="","",I41-J41))) | P41: =if(N41="",O41,(if(O41="","",N41-O41))) | R41: FALSE
F42: FALSE | K42: =if(I42="",J42,(if(J42="","",I42-J42))) | P42: =if(N42="",O42,(if(O42="","",N42-O42))) | R42: FALSE
C43: Budget | D43: Actual | F43: FALSE | K43: =if(I43="",J43,(if(J43="","",I43-J43))) | P43: =if(N43="",O43,(if(O43="","",N43-O43))) | R43: FALSE
B44: Car | F44: FALSE | K44: =if(I44="",J44,(if(J44="","",I44-J44))) | P44: =if(N44="",O44,(if(O44="","",N44-O44))) | R44: FALSE
B45: Renovation | F45: FALSE | K45: =if(I45="",J45,(if(J45="","",I45-J45))) | P45: =if(N45="",O45,(if(O45="","",N45-O45))) | R45: FALSE
...

Sheet July
C2: July
B4: Overview | F4: INCOME | J4: Left to Spend | N4: Bills & Expenses | Q4: Debt Payments | U4: Savings
B6: Start Date | C6: 45839
B7: End Date | C7: 45869 | F7: =D15 -> 0 | J7: =D19 -> 0 | N7: =D17 -> 0 | Q7: =D18 -> 0 | U7: =D16 -> 0
B8: Currency | C8: $
B9: Start Balance | C9: =June!J7 -> 0
B10: spent | C10: =D16+D17+D18 -> 0 | D10: =D19 -> 0
B11: Cashflow
AD12: debt | AE12: =V49 -> 0
C13: Budget | D13: Actual | AD13: bills | AE13: =J63 -> 0
B14: Start Balance | C14: =C9 -> 0 | D14: =C9 -> 0 | AD14: expenses | AE14: =O63 -> 0
B15: Income | C15: =C29+C39 -> 0 | D15: =D29+D39 -> 0 | I15: =D19 -> 0 | AD15: savings | AE15: =D63 -> 0
B16: Savings | C16: =C63 -> 0 | D16: =D63 -> 0
B17: Bills & Expenses | C17: =I63+N63 -> 0 | D17: =J63+O63 -> 0
B18: Debt | C18: =U49 -> 0 | D18: =V49 -> 0
B19: Left | C19: =C14+C15-C16-C17-C18 -> 0 | D19: =D14+D15-D17-D18-D16 -> 0
B21: Primary Income | F21: Bills | M21: Expenses | R21: Debt
C23: Estimated | D23: Actual | H23: Due | I23: Budget | J23: Actual | K23: Left | N23: Budget | O23: Actual | P23: Left | T23: Due | U23: Budget | V23: Actual
B24: Paycheck | F24: FALSE | K24: =if(I24="",J24,(if(J24="","",I24-J24))) | P24: =if(N24="",O24,(if(O24="","",N24-O24))) | R24: FALSE
B25: Paycheck 2 | F25: FALSE | K25: =if(I25="",J25,(if(J25="","",I25-J25))) | P25: =if(N25="",O25,(if(O25="","",N25-O25))) | R25: FALSE
B26: Bonus | F26: FALSE | K26: =if(I26="",J26,(if(J26="","",I26-J26))) | P26: =if(N26="",O26,(if(O26="","",N26-O26))) | R26: FALSE
B27: Gifts | F27: FALSE | K27: =if(I27="",J27,(if(J27="","",I27-J27))) | P27: =if(N27="",O27,(if(O27="","",N27-O27))) | R27: FALSE
B28: Freelancing work | F28: FALSE | K28: =if(I28="",J28,(if(J28="","",I28-J28))) | P28: =if(N28="",O28,(if(O28="","",N28-O28))) | R28: FALSE
B29: Total | C29: =sum(C24:C28) -> 0 | D29: =sum(D24:D28) -> 0 | F29: FALSE | K29: =if(I29="",J29,(if(J29="","",I29-J29))) | P29: =if(N29="",O29,(if(O29="","",N29-O29))) | R29: FALSE
F30: FALSE | K30: =if(I30="",J30,(if(J30="","",I30-J30))) | P30: =if(N30="",O30,(if(O30="","",N30-O30))) | R30: FALSE
B31: Secondary Income | F31: FALSE | K31: =if(I31="",J31,(if(J31="","",I31-J31))) | P31: =if(N31="",O31,(if(O31="","",N31-O31))) | R31: FALSE
F32: FALSE | K32: =if(I32="",J32,(if(J32="","",I32-J32))) | P32: =if(N32="",O32,(if(O32="","",N32-O32))) | R32: FALSE
C33: Estimated | D33: Actual | F33: FALSE | K33: =if(I33="",J33,(if(J33="","",I33-J33))) | P33: =if(N33="",O33,(if(O33="","",N33-O33))) | R33: FALSE
B34: Capital Gains | F34: FALSE | K34: =if(I34="",J34,(if(J34="","",I34-J34))) | P34: =if(N34="",O34,(if(O34="","",N34-O34))) | R34: FALSE
B35: Stocks | F35: FALSE | K35: =if(I35="",J35,(if(J35="","",I35-J35))) | P35: =if(N35="",O35,(if(O35="","",N35-O35))) | R35: FALSE
B36: Rental Income | F36: FALSE | K36: =if(I36="",J36,(if(J36="","",I36-J36))) | P36: =if(N36="",O36,(if(O36="","",N36-O36))) | R36: FALSE
B37: Interests | F37: FALSE | P37: =if(N37="",O37,(if(O37="","",N37-O37))) | R37: FALSE
B38: Side Hustle | F38: FALSE | K38: =if(I38="",J38,(if(J38="","",I38-J38))) | P38: =if(N38="",O38,(if(O38="","",N38-O38))) | R38: FALSE
B39: Total | C39: =SUM(C34:C38) -> 0 | D39: =sum(D34:D38) -> 0 | F39: FALSE | K39: =if(I39="",J39,(if(J39="","",I39-J39))) | P39: =if(N39="",O39,(if(O39="","",N39-O39))) | R39: FALSE
F40: FALSE | K40: =if(I40="",J40,(if(J40="","",I40-J40))) | P40: =if(N40="",O40,(if(O40="","",N40-O40))) | R40: FALSE
B41: Saving For | F41: FALSE | K41: =if(I41="",J41,(if(J41="","",I41-J41))) | P41: =if(N41="",O41,(if(O41="","",N41-O41))) | R41: FALSE
F42: FALSE | K42: =if(I42="",J42,(if(J42="","",I42-J42))) | P42: =if(N42="",O42,(if(O42="","",N42-O42))) | R42: FALSE
C43: Budget | D43: Actual | F43: FALSE | K43: =if(I43="",J43,(if(J43="","",I43-J43))) | P43: =if(N43="",O43,(if(O43="","",N43-O43))) | R43: FALSE
B44: Car | F44: FALSE | K44: =if(I44="",J44,(if(J44="","",I44-J44))) | P44: =if(N44="",O44,(if(O44="","",N44-O44))) | R44: FALSE
B45: Renovation | F45: FALSE | K45: =if(I45="",J45,(if(J45="","",I45-J45))) | P45: =if(N45="",O45,(if(O45="","",N45-O45))) | R45: FALSE
...

Sheet August
C2: August
B4: Overview | F4: INCOME | J4: Left to Spend | N4: Bills & Expenses | Q4: Debt Payments | U4: Savings
B6: Start Date | C6: 45870
B7: End Date | C7: 45900 | F7: =D15 -> 0 | J7: =D19 -> 0 | N7: =D17 -> 0 | Q7: =D18 -> 0 | U7: =D16 -> 0
B8: Currency | C8: $
B9: Start Balance | C9: =July!J7 -> 0
B10: spent | C10: =D16+D17+D18 -> 0 | D10: =D19 -> 0
B11: Cashflow
AD12: debt | AE12: =V49 -> 0
C13: Budget | D13: Actual | AD13: bills | AE13: =J63 -> 0
B14: Start Balance | C14: =C9 -> 0 | D14: =C9 -> 0 | AD14: expenses | AE14: =O63 -> 0
B15: Income | C15: =C29+C39 -> 0 | D15: =D29+D39 -> 0 | I15: =D19 -> 0 | AD15: savings | AE15: =D63 -> 0
B16: Savings | C16: =C63 -> 0 | D16: =D63 -> 0
B17: Bills & Expenses | C17: =I63+N63 -> 0 | D17: =J63+O63 -> 0
B18: Debt | C18: =U49 -> 0 | D18: =V49 -> 0
B19: Left | C19: =C14+C15-C16-C17-C18 -> 0 | D19: =D14+D15-D17-D18-D16 -> 0
B21: Primary Income | F21: Bills | M21: Expenses | R21: Debt
C23: Estimated | D23: Actual | H23: Due | I23: Budget | J23: Actual | K23: Left | N23: Budget | O23: Actual | P23: Left | T23: Due | U23: Budget | V23: Actual
B24: Paycheck | F24: FALSE | K24: =if(I24="",J24,(if(J24="","",I24-J24))) | P24: =if(N24="",O24,(if(O24="","",N24-O24))) | R24: FALSE
B25: Paycheck 2 | F25: FALSE | K25: =if(I25="",J25,(if(J25="","",I25-J25))) | P25: =if(N25="",O25,(if(O25="","",N25-O25))) | R25: FALSE
B26: Bonus | F26: FALSE | K26: =if(I26="",J26,(if(J26="","",I26-J26))) | P26: =if(N26="",O26,(if(O26="","",N26-O26))) | R26: FALSE
B27: Gifts | F27: FALSE | K27: =if(I27="",J27,(if(J27="","",I27-J27))) | P27: =if(N27="",O27,(if(O27="","",N27-O27))) | R27: FALSE
B28: Freelancing work | F28: FALSE | K28: =if(I28="",J28,(if(J28="","",I28-J28))) | P28: =if(N28="",O28,(if(O28="","",N28-O28))) | R28: FALSE
B29: Total | C29: =sum(C24:C28) -> 0 | D29: =sum(D24:D28) -> 0 | F29: FALSE | K29: =if(I29="",J29,(if(J29="","",I29-J29))) | P29: =if(N29="",O29,(if(O29="","",N29-O29))) | R29: FALSE
F30: FALSE | K30: =if(I30="",J30,(if(J30="","",I30-J30))) | P30: =if(N30="",O30,(if(O30="","",N30-O30))) | R30: FALSE
B31: Secondary Income | F31: FALSE | K31: =if(I31="",J31,(if(J31="","",I31-J31))) | P31: =if(N31="",O31,(if(O31="","",N31-O31))) | R31: FALSE
F32: FALSE | K32: =if(I32="",J32,(if(J32="","",I32-J32))) | P32: =if(N32="",O32,(if(O32="","",N32-O32))) | R32: FALSE
C33: Estimated | D33: Actual | F33: FALSE | K33: =if(I33="",J33,(if(J33="","",I33-J33))) | P33: =if(N33="",O33,(if(O33="","",N33-O33))) | R33: FALSE
B34: Capital Gains | F34: FALSE | K34: =if(I34="",J34,(if(J34="","",I34-J34))) | P34: =if(N34="",O34,(if(O34="","",N34-O34))) | R34: FALSE
B35: Stocks | F35: FALSE | K35: =if(I35="",J35,(if(J35="","",I35-J35))) | P35: =if(N35="",O35,(if(O35="","",N35-O35))) | R35: FALSE
B36: Rental Income | F36: FALSE | K36: =if(I36="",J36,(if(J36="","",I36-J36))) | P36: =if(N36="",O36,(if(O36="","",N36-O36))) | R36: FALSE
B37: Interests | F37: FALSE | P37: =if(N37="",O37,(if(O37="","",N37-O37))) | R37: FALSE
B38: Side Hustle | F38: FALSE | K38: =if(I38="",J38,(if(J38="","",I38-J38))) | P38: =if(N38="",O38,(if(O38="","",N38-O38))) | R38: FALSE
B39: Total | C39: =SUM(C34:C38) -> 0 | D39: =sum(D34:D38) -> 0 | F39: FALSE | K39: =if(I39="",J39,(if(J39="","",I39-J39))) | P39: =if(N39="",O39,(if(O39="","",N39-O39))) | R39: FALSE
F40: FALSE | K40: =if(I40="",J40,(if(J40="","",I40-J40))) | P40: =if(N40="",O40,(if(O40="","",N40-O40))) | R40: FALSE
B41: Saving For | F41: FALSE | K41: =if(I41="",J41,(if(J41="","",I41-J41))) | P41: =if(N41="",O41,(if(O41="","",N41-O41))) | R41: FALSE
F42: FALSE | K42: =if(I42="",J42,(if(J42="","",I42-J42))) | P42: =if(N42="",O42,(if(O42="","",N42-O42))) | R42: FALSE
C43: Budget | D43: Actual | F43: FALSE | K43: =if(I43="",J43,(if(J43="","",I43-J43))) | P43: =if(N43="",O43,(if(O43="","",N43-O43))) | R43: FALSE
B44: Car | F44: FALSE | K44: =if(I44="",J44,(if(J44="","",I44-J44))) | P44: =if(N44="",O44,(if(O44="","",N44-O44))) | R44: FALSE
B45: Renovation | F45: FALSE | K45: =if(I45="",J45,(if(J45="","",I45-J45))) | P45: =if(N45="",O45,(if(O45="","",N45-O45))) | R45: FALSE
...

Sheet September
C2: September
B4: Overview | F4: INCOME | J4: Left to Spend | N4: Bills & Expenses | Q4: Debt Payments | U4: Savings
B6: Start Date | C6: 45901
B7: End Date | C7: 45930 | F7: =D15 -> 0 | J7: =D19 -> 0 | N7: =D17 -> 0 | Q7: =D18 -> 0 | U7: =D16 -> 0
B8: Currency | C8: $
B9: Start Balance | C9: =August!J7 -> 0
B10: spent | C10: =D16+D17+D18 -> 0 | D10: =D19 -> 0
B11: Cashflow
AD12: debt | AE12: =V49 -> 0
C13: Budget | D13: Actual | AD13: bills | AE13: =J63 -> 0
B14: Start Balance | C14: =C9 -> 0 | D14: =C9 -> 0 | AD14: expenses | AE14: =O63 -> 0
B15: Income | C15: =C29+C39 -> 0 | D15: =D29+D39 -> 0 | I15: =D19 -> 0 | AD15: savings | AE15: =D63 -> 0
B16: Savings | C16: =C63 -> 0 | D16: =D63 -> 0
B17: Bills & Expenses | C17: =I63+N63 -> 0 | D17: =J63+O63 -> 0
B18: Debt | C18: =U49 -> 0 | D18: =V49 -> 0
B19: Left | C19: =C14+C15-C16-C17-C18 -> 0 | D19: =D14+D15-D17-D18-D16 -> 0
B21: Primary Income | F21: Bills | M21: Expenses | R21: Debt
C23: Estimated | D23: Actual | H23: Due | I23: Budget | J23: Actual | K23: Left | N23: Budget | O23: Actual | P23: Left | T23: Due | U23: Budget | V23: Actual
B24: Paycheck | F24: FALSE | K24: =if(I24="",J24,(if(J24="","",I24-J24))) | P24: =if(N24="",O24,(if(O24="","",N24-O24))) | R24: FALSE
B25: Paycheck 2 | F25: FALSE | K25: =if(I25="",J25,(if(J25="","",I25-J25))) | P25: =if(N25="",O25,(if(O25="","",N25-O25))) | R25: FALSE
B26: Bonus | F26: FALSE | K26: =if(I26="",J26,(if(J26="","",I26-J26))) | P26: =if(N26="",O26,(if(O26="","",N26-O26))) | R26: FALSE
B27: Gifts | F27: FALSE | K27: =if(I27="",J27,(if(J27="","",I27-J27))) | P27: =if(N27="",O27,(if(O27="","",N27-O27))) | R27: FALSE
B28: Freelancing work | F28: FALSE | K28: =if(I28="",J28,(if(J28="","",I28-J28))) | P28: =if(N28="",O28,(if(O28="","",N28-O28))) | R28: FALSE
B29: Total | C29: =sum(C24:C28) -> 0 | D29: =sum(D24:D28) -> 0 | F29: FALSE | K29: =if(I29="",J29,(if(J29="","",I29-J29))) | P29: =if(N29="",O29,(if(O29="","",N29-O29))) | R29: FALSE
F30: FALSE | K30: =if(I30="",J30,(if(J30="","",I30-J30))) | P30: =if(N30="",O30,(if(O30="","",N30-O30))) | R30: FALSE
B31: Secondary Income | F31: FALSE | K31: =if(I31="",J31,(if(J31="","",I31-J31))) | P31: =if(N31="",O31,(if(O31="","",N31-O31))) | R31: FALSE
F32: FALSE | K32: =if(I32="",J32,(if(J32="","",I32-J32))) | P32: =if(N32="",O32,(if(O32="","",N32-O32))) | R32: FALSE
C33: Estimated | D33: Actual | F33: FALSE | K33: =if(I33="",J33,(if(J33="","",I33-J33))) | P33: =if(N33="",O33,(if(O33="","",N33-O33))) | R33: FALSE
B34: Capital Gains | F34: FALSE | K34: =if(I34="",J34,(if(J34="","",I34-J34))) | P34: =if(N34="",O34,(if(O34="","",N34-O34))) | R34: FALSE
B35: Stocks | F35: FALSE | K35: =if(I35="",J35,(if(J35="","",I35-J35))) | P35: =if(N35="",O35,(if(O35="","",N35-O35))) | R35: FALSE
B36: Rental Income | F36: FALSE | K36: =if(I36="",J36,(if(J36="","",I36-J36))) | P36: =if(N36="",O36,(if(O36="","",N36-O36))) | R36: FALSE
B37: Interests | F37: FALSE | P37: =if(N37="",O37,(if(O37="","",N37-O37))) | R37: FALSE
B38: Side Hustle | F38: FALSE | K38: =if(I38="",J38,(if(J38="","",I38-J38))) | P38: =if(N38="",O38,(if(O38="","",N38-O38))) | R38: FALSE
B39: Total | C39: =SUM(C34:C38) -> 0 | D39: =sum(D34:D38) -> 0 | F39: FALSE | K39: =if(I39="",J39,(if(J39="","",I39-J39))) | P39: =if(N39="",O39,(if(O39="","",N39-O39))) | R39: FALSE
F40: FALSE | K40: =if(I40="",J40,(if(J40="","",I40-J40))) | P40: =if(N40="",O40,(if(O40="","",N40-O40))) | R40: FALSE
B41: Saving For | F41: FALSE | K41: =if(I41="",J41,(if(J41="","",I41-J41))) | P41: =if(N41="",O41,(if(O41="","",N41-O41))) | R41: FALSE
F42: FALSE | K42: =if(I42="",J42,(if(J42="","",I42-J42))) | P42: =if(N42="",O42,(if(O42="","",N42-O42))) | R42: FALSE
C43: Budget | D43: Actual | F43: FALSE | K43: =if(I43="",J43,(if(J43="","",I43-J43))) | P43: =if(N43="",O43,(if(O43="","",N43-O43))) | R43: FALSE
B44: Car | F44: FALSE | K44: =if(I44="",J44,(if(J44="","",I44-J44))) | P44: =if(N44="",O44,(if(O44="","",N44-O44))) | R44: FALSE
B45: Renovation | F45: FALSE | K45: =if(I45="",J45,(if(J45="","",I45-J45))) | P45: =if(N45="",O45,(if(O45="","",N45-O45))) | R45: FALSE
...

Sheet October
C2: October
B4: Overview | F4: INCOME | J4: Left to Spend | N4: Bills & Expenses | Q4: Debt Payments | U4: Savings
B6: Start Date | C6: 45931
B7: End Date | C7: 45961 | F7: =D15 -> 0 | J7: =D19 -> 0 | N7: =D17 -> 0 | Q7: =D18 -> 0 | U7: =D16 -> 0
B8: Currency | C8: $
B9: Start Balance | C9: =September!J7 -> 0
B10: spent | C10: =D16+D17+D18 -> 0 | D10: =D19 -> 0
B11: Cashflow
AD12: debt | AE12: =V49 -> 0
C13: Budget | D13: Actual | AD13: bills | AE13: =J63 -> 0
B14: Start Balance | C14: =C9 -> 0 | D14: =C9 -> 0 | AD14: expenses | AE14: =O63 -> 0
B15: Income | C15: =C29+C39 -> 0 | D15: =D29+D39 -> 0 | I15: =D19 -> 0 | AD15: savings | AE15: =D63 -> 0
B16: Savings | C16: =C63 -> 0 | D16: =D63 -> 0
B17: Bills & Expenses | C17: =I63+N63 -> 0 | D17: =J63+O63 -> 0
B18: Debt | C18: =U49 -> 0 | D18: =V49 -> 0
B19: Left | C19: =C14+C15-C16-C17-C18 -> 0 | D19: =D14+D15-D17-D18-D16 -> 0
B21: Primary Income | F21: Bills | M21: Expenses | R21: Debt
C23: Estimated | D23: Actual | H23: Due | I23: Budget | J23: Actual | K23: Left | N23: Budget | O23: Actual | P23: Left | T23: Due | U23: Budget | V23: Actual
B24: Paycheck | F24: FALSE | K24: =if(I24="",J24,(if(J24="","",I24-J24))) | P24: =if(N24="",O24,(if(O24="","",N24-O24))) | R24: FALSE
B25: Paycheck 2 | F25: FALSE | K25: =if(I25="",J25,(if(J25="","",I25-J25))) | P25: =if(N25="",O25,(if(O25="","",N25-O25))) | R25: FALSE
B26: Bonus | F26: FALSE | K26: =if(I26="",J26,(if(J26="","",I26-J26))) | P26: =if(N26="",O26,(if(O26="","",N26-O26))) | R26: FALSE
B27: Gifts | F27: FALSE | K27: =if(I27="",J27,(if(J27="","",I27-J27))) | P27: =if(N27="",O27,(if(O27="","",N27-O27))) | R27: FALSE
B28: Freelancing work | F28: FALSE | K28: =if(I28="",J28,(if(J28="","",I28-J28))) | P28: =if(N28="",O28,(if(O28="","",N28-O28))) | R28: FALSE
B29: Total | C29: =sum(C24:C28) -> 0 | D29: =sum(D24:D28) -> 0 | F29: FALSE | K29: =if(I29="",J29,(if(J29="","",I29-J29))) | P29: =if(N29="",O29,(if(O29="","",N29-O29))) | R29: FALSE
F30: FALSE | K30: =if(I30="",J30,(if(J30="","",I30-J30))) | P30: =if(N30="",O30,(if(O30="","",N30-O30))) | R30: FALSE
B31: Secondary Income | F31: FALSE | K31: =if(I31="",J31,(if(J31="","",I31-J31))) | P31: =if(N31="",O31,(if(O31="","",N31-O31))) | R31: FALSE
F32: FALSE | K32: =if(I32="",J32,(if(J32="","",I32-J32))) | P32: =if(N32="",O32,(if(O32="","",N32-O32))) | R32: FALSE
C33: Estimated | D33: Actual | F33: FALSE | K33: =if(I33="",J33,(if(J33="","",I33-J33))) | P33: =if(N33="",O33,(if(O33="","",N33-O33))) | R33: FALSE
B34: Capital Gains | F34: FALSE | K34: =if(I34="",J34,(if(J34="","",I34-J34))) | P34: =if(N34="",O34,(if(O34="","",N34-O34))) | R34: FALSE
B35: Stocks | F35: FALSE | K35: =if(I35="",J35,(if(J35="","",I35-J35))) | P35: =if(N35="",O35,(if(O35="","",N35-O35))) | R35: FALSE
B36: Rental Income | F36: FALSE | K36: =if(I36="",J36,(if(J36="","",I36-J36))) | P36: =if(N36="",O36,(if(O36="","",N36-O36))) | R36: FALSE
B37: Interests | F37: FALSE | P37: =if(N37="",O37,(if(O37="","",N37-O37))) | R37: FALSE
B38: Side Hustle | F38: FALSE | K38: =if(I38="",J38,(if(J38="","",I38-J38))) | P38: =if(N38="",O38,(if(O38="","",N38-O38))) | R38: FALSE
B39: Total | C39: =SUM(C34:C38) -> 0 | D39: =sum(D34:D38) -> 0 | F39: FALSE | K39: =if(I39="",J39,(if(J39="","",I39-J39))) | P39: =if(N39="",O39,(if(O39="","",N39-O39))) | R39: FALSE
F40: FALSE | K40: =if(I40="",J40,(if(J40="","",I40-J40))) | P40: =if(N40="",O40,(if(O40="","",N40-O40))) | R40: FALSE
B41: Saving For | F41: FALSE | K41: =if(I41="",J41,(if(J41="","",I41-J41))) | P41: =if(N41="",O41,(if(O41="","",N41-O41))) | R41: FALSE
F42: FALSE | K42: =if(I42="",J42,(if(J42="","",I42-J42))) | P42: =if(N42="",O42,(if(O42="","",N42-O42))) | R42: FALSE
C43: Budget | D43: Actual | F43: FALSE | K43: =if(I43="",J43,(if(J43="","",I43-J43))) | P43: =if(N43="",O43,(if(O43="","",N43-O43))) | R43: FALSE
B44: Car | F44: FALSE | K44: =if(I44="",J44,(if(J44="","",I44-J44))) | P44: =if(N44="",O44,(if(O44="","",N44-O44))) | R44: FALSE
B45: Renovation | F45: FALSE | K45: =if(I45="",J45,(if(J45="","",I45-J45))) | P45: =if(N45="",O45,(if(O45="","",N45-O45))) | R45: FALSE
...

Sheet November
C2: November
B4: Overview | F4: INCOME | J4: Left to Spend | N4: Bills & Expenses | Q4: Debt Payments | U4: Savings
B6: Start Date | C6: 45962
B7: End Date | C7: 45991 | F7: =D15 -> 0 | J7: =D19 -> 0 | N7: =D17 -> 0 | Q7: =D18 -> 0 | U7: =D16 -> 0
B8: Currency | C8: $
B9: Start Balance | C9: =October!J7 -> 0
B10: spent | C10: =D16+D17+D18 -> 0 | D10: =D19 -> 0
B11: Cashflow
AD12: debt | AE12: =V49 -> 0
C13: Budget | D13: Actual | AD13: bills | AE13: =J63 -> 0
B14: Start Balance | C14: =C9 -> 0 | D14: =C9 -> 0 | AD14: expenses | AE14: =O63 -> 0
B15: Income | C15: =C29+C39 -> 0 | D15: =D29+D39 -> 0 | I15: =D19 -> 0 | AD15: savings | AE15: =D63 -> 0
B16: Savings | C16: =C63 -> 0 | D16: =D63 -> 0
B17: Bills & Expenses | C17: =I63+N63 -> 0 | D17: =J63+O63 -> 0
B18: Debt | C18: =U49 -> 0 | D18: =V49 -> 0
B19: Left | C19: =C14+C15-C16-C17-C18 -> 0 | D19: =D14+D15-D17-D18-D16 -> 0
B21: Primary Income | F21: Bills | M21: Expenses | R21: Debt
C23: Estimated | D23: Actual | H23: Due | I23: Budget | J23: Actual | K23: Left | N23: Budget | O23: Actual | P23: Left | T23: Due | U23: Budget | V23: Actual
B24: Paycheck | F24: FALSE | K24: =if(I24="",J24,(if(J24="","",I24-J24))) | P24: =if(N24="",O24,(if(O24="","",N24-O24))) | R24: FALSE
B25: Paycheck 2 | F25: FALSE | K25: =if(I25="",J25,(if(J25="","",I25-J25))) | P25: =if(N25="",O25,(if(O25="","",N25-O25))) | R25: FALSE
B26: Bonus | F26: FALSE | K26: =if(I26="",J26,(if(J26="","",I26-J26))) | P26: =if(N26="",O26,(if(O26="","",N26-O26))) | R26: FALSE
B27: Gifts | F27: FALSE | K27: =if(I27="",J27,(if(J27="","",I27-J27))) | P27: =if(N27="",O27,(if(O27="","",N27-O27))) | R27: FALSE
B28: Freelancing work | F28: FALSE | K28: =if(I28="",J28,(if(J28="","",I28-J28))) | P28: =if(N28="",O28,(if(O28="","",N28-O28))) | R28: FALSE
B29: Total | C29: =sum(C24:C28) -> 0 | D29: =sum(D24:D28) -> 0 | F29: FALSE | K29: =if(I29="",J29,(if(J29="","",I29-J29))) | P29: =if(N29="",O29,(if(O29="","",N29-O29))) | R29: FALSE
F30: FALSE | K30: =if(I30="",J30,(if(J30="","",I30-J30))) | P30: =if(N30="",O30,(if(O30="","",N30-O30))) | R30: FALSE
B31: Secondary Income | F31: FALSE | K31: =if(I31="",J31,(if(J31="","",I31-J31))) | P31: =if(N31="",O31,(if(O31="","",N31-O31))) | R31: FALSE
F32: FALSE | K32: =if(I32="",J32,(if(J32="","",I32-J32))) | P32: =if(N32="",O32,(if(O32="","",N32-O32))) | R32: FALSE
C33: Estimated | D33: Actual | F33: FALSE | K33: =if(I33="",J33,(if(J33="","",I33-J33))) | P33: =if(N33="",O33,(if(O33="","",N33-O33))) | R33: FALSE
B34: Capital Gains | F34: FALSE | K34: =if(I34="",J34,(if(J34="","",I34-J34))) | P34: =if(N34="",O34,(if(O34="","",N34-O34))) | R34: FALSE
B35: Stocks | F35: FALSE | K35: =if(I35="",J35,(if(J35="","",I35-J35))) | P35: =if(N35="",O35,(if(O35="","",N35-O35))) | R35: FALSE
B36: Rental Income | F36: FALSE | K36: =if(I36="",J36,(if(J36="","",I36-J36))) | P36: =if(N36="",O36,(if(O36="","",N36-O36))) | R36: FALSE
B37: Interests | F37: FALSE | P37: =if(N37="",O37,(if(O37="","",N37-O37))) | R37: FALSE
B38: Side Hustle | F38: FALSE | K38: =if(I38="",J38,(if(J38="","",I38-J38))) | P38: =if(N38="",O38,(if(O38="","",N38-O38))) | R38: FALSE
B39: Total | C39: =SUM(C34:C38) -> 0 | D39: =sum(D34:D38) -> 0 | F39: FALSE | K39: =if(I39="",J39,(if(J39="","",I39-J39))) | P39: =if(N39="",O39,(if(O39="","",N39-O39))) | R39: FALSE
F40: FALSE | K40: =if(I40="",J40,(if(J40="","",I40-J40))) | P40: =if(N40="",O40,(if(O40="","",N40-O40))) | R40: FALSE
B41: Saving For | F41: FALSE | K41: =if(I41="",J41,(if(J41="","",I41-J41))) | P41: =if(N41="",O41,(if(O41="","",N41-O41))) | R41: FALSE
F42: FALSE | K42: =if(I42="",J42,(if(J42="","",I42-J42))) | P42: =if(N42="",O42,(if(O42="","",N42-O42))) | R42: FALSE
C43: Budget | D43: Actual | F43: FALSE | K43: =if(I43="",J43,(if(J43="","",I43-J43))) | P43: =if(N43="",O43,(if(O43="","",N43-O43))) | R43: FALSE
B44: Car | F44: FALSE | K44: =if(I44="",J44,(if(J44="","",I44-J44))) | P44: =if(N44="",O44,(if(O44="","",N44-O44))) | R44: FALSE
B45: Renovation | F45: FALSE | K45: =if(I45="",J45,(if(J45="","",I45-J45))) | P45: =if(N45="",O45,(if(O45="","",N45-O45))) | R45: FALSE
...

Sheet December
C2: December
B4: Overview | F4: INCOME | J4: Left to Spend | N4: Bills & Expenses | Q4: Debt Payments | U4: Savings
B6: Start Date | C6: 45992
B7: End Date | C7: 46022 | F7: =D15 -> 0 | J7: =D19 -> 0 | N7: =D17 -> 0 | Q7: =D18 -> 0 | U7: =D16 -> 0
B8: Currency | C8: $
B9: Start Balance | C9: =November!J7 -> 0
B10: spent | C10: =D16+D17+D18 -> 0 | D10: =D19 -> 0
B11: Cashflow
AD12: debt | AE12: =V49 -> 0
C13: Budget | D13: Actual | AD13: bills | AE13: =J63 -> 0
B14: Start Balance | C14: =C9 -> 0 | D14: =C9 -> 0 | AD14: expenses | AE14: =O63 -> 0
B15: Income | C15: =C29+C39 -> 0 | D15: =D29+D39 -> 0 | I15: =D19 -> 0 | AD15: savings | AE15: =D63 -> 0
B16: Savings | C16: =C63 -> 0 | D16: =D63 -> 0
B17: Bills & Expenses | C17: =I63+N63 -> 0 | D17: =J63+O63 -> 0
B18: Debt | C18: =U49 -> 0 | D18: =V49 -> 0
